Traceback (most recent call last):
  File "/cow02/rudenko/colowils/Miniconda3/envs/LLM/lib/python3.11/site-packages/pandas/core/indexes/base.py", line 3653, in get_loc
    return self._engine.get_loc(casted_key)
           ^^^^^^^^^^^^^^^^^^^^^^^^^^^^^^^^
  File "pandas/_libs/index.pyx", line 147, in pandas._libs.index.IndexEngine.get_loc
  File "pandas/_libs/index.pyx", line 176, in pandas._libs.index.IndexEngine.get_loc
  File "pandas/_libs/hashtable_class_helper.pxi", line 7080, in pandas._libs.hashtable.PyObjectHashTable.get_item
  File "pandas/_libs/hashtable_class_helper.pxi", line 7088, in pandas._libs.hashtable.PyObjectHashTable.get_item
KeyError: 0

The above exception was the direct cause of the following exception:

Traceback (most recent call last):
  File "/cow02/rudenko/colowils/LLMExp/LLM-Exp/tokenizers/hendrykcstoken.py", line 8, in <module>
    questions = data[0].tolist()
                ~~~~^^^
  File "/cow02/rudenko/colowils/Miniconda3/envs/LLM/lib/python3.11/site-packages/pandas/core/frame.py", line 3761, in __getitem__
    indexer = self.columns.get_loc(key)
              ^^^^^^^^^^^^^^^^^^^^^^^^^
  File "/cow02/rudenko/colowils/Miniconda3/envs/LLM/lib/python3.11/site-packages/pandas/core/indexes/base.py", line 3655, in get_loc
    raise KeyError(key) from err
KeyError: 0